<!-- Generated on 2025-01-31 07:39:09 -->
<robot name='UR3'>
	<material name='blue'>
		<color rgba='0 0 0.8 1'/>
	</material>
	<material name='red'>
		<color rgba='0.8 0 0 1'/>
	</material>

    <link name='a0'>
        <visual>
            <origin rpy='-0.0 0.0 0.0' xyz='0.0 0.0 0.0'/>
            <geometry>
                <cylinder length='0.1' radius='0.05'/>
            </geometry>
            <material name='blue'/>
        </visual>
        <inertial>
            <mass value='0'/>
            <inertia ixx='1e-3' ixy='0' ixz='0' iyy='1e-3' iyz='0' izz='1e-3'/>
            <origin xyz='0 0 0'/>
        </inertial>
    </link>
    
    <link name='l0'>
        <visual>
            <origin rpy='-0.0 0.0 0.0' xyz='0.0 0.0 0.07595'/>
            <geometry>
                <cylinder length='0.1519' radius='0.05'/>
            </geometry>
            <material name='red'/>
        </visual>
    </link>
    
    <joint name='move_l0_from_a0' type='continuous'>
        <parent link='a0'/>
        <child link='l0'/>
        <axis xyz='0.0 0.0 1.0'/>
        <origin rpy='0 0 0' xyz='0 0 0.1519'/>
        <limit lower='-3.14' upper='3.14'/>
    </joint>
    
    <link name='a1'>
        <visual>
            <origin rpy='1.5708 0.0 0.0' xyz='0.0 0.0 0.1519'/>
            <geometry>
                <cylinder length='0.1' radius='0.05'/>
            </geometry>
            <material name='blue'/>
        </visual>
        <inertial>
            <mass value='2.0'/>
            <inertia ixx='1e-3' ixy='0' ixz='0' iyy='1e-3' iyz='0' izz='1e-3'/>
            <origin xyz='0 -0.02 0'/>
        </inertial>
    </link>
    
    <joint name='fix_a1_to_l0' type='fixed'>
        <parent link='l0'/>
        <child link='a1'/>
        <origin rpy='0 0 0' xyz='0 0 0'/>
    </joint>
    
    <link name='l1'>
        <visual>
            <origin rpy='-0.0 -1.5707963267948966 0.0' xyz='-0.121825 -0.0 0.0'/>
            <geometry>
                <cylinder length='0.24365' radius='0.05'/>
            </geometry>
            <material name='red'/>
        </visual>
    </link>
    
    <joint name='move_l1_from_a1' type='continuous'>
        <parent link='a1'/>
        <child link='l1'/>
        <axis xyz='0.0 -0.9999999999932537 -3.673205103346574e-06'/>
        <origin rpy='0 0 0' xyz='-0.24365 0 0'/>
        <limit lower='-3.14' upper='3.14'/>
    </joint>
    
    <link name='a2'>
        <visual>
            <origin rpy='1.5708 0.0 0.0' xyz='-0.24365 -0.0 0.0'/>
            <geometry>
                <cylinder length='0.1' radius='0.05'/>
            </geometry>
            <material name='blue'/>
        </visual>
        <inertial>
            <mass value='3.42'/>
            <inertia ixx='1e-3' ixy='0' ixz='0' iyy='1e-3' iyz='0' izz='1e-3'/>
            <origin xyz='0.13 0 0.1157'/>
        </inertial>
    </link>
    
    <joint name='fix_a2_to_l1' type='fixed'>
        <parent link='l1'/>
        <child link='a2'/>
        <origin rpy='0 0 0' xyz='0 0 0'/>
    </joint>
    
    <link name='l2'>
        <visual>
            <origin rpy='-0.0 -1.5707963267948966 0.0' xyz='-0.106625 -0.0 0.0'/>
            <geometry>
                <cylinder length='0.21325' radius='0.05'/>
            </geometry>
            <material name='red'/>
        </visual>
    </link>
    
    <joint name='move_l2_from_a2' type='continuous'>
        <parent link='a2'/>
        <child link='l2'/>
        <axis xyz='0.0 -0.9999999999932537 -3.673205103346574e-06'/>
        <origin rpy='0 0 0' xyz='-0.21325 0 0'/>
        <limit lower='-3.14' upper='3.14'/>
    </joint>
    
    <link name='a3'>
        <visual>
            <origin rpy='1.5708 0.0 0.0' xyz='-0.21325 -0.0 0.0'/>
            <geometry>
                <cylinder length='0.1' radius='0.05'/>
            </geometry>
            <material name='blue'/>
        </visual>
        <inertial>
            <mass value='1.26'/>
            <inertia ixx='1e-3' ixy='0' ixz='0' iyy='1e-3' iyz='0' izz='1e-3'/>
            <origin xyz='0.05 0 0.0238'/>
        </inertial>
    </link>
    
    <joint name='fix_a3_to_l2' type='fixed'>
        <parent link='l2'/>
        <child link='a3'/>
        <origin rpy='0 0 0' xyz='0 0 0'/>
    </joint>
    
    <link name='l3'>
        <visual>
            <origin rpy='-0.0 0.0 0.0' xyz='0.0 0.0 0.056175'/>
            <geometry>
                <cylinder length='0.11235' radius='0.05'/>
            </geometry>
            <material name='red'/>
        </visual>
    </link>
    
    <joint name='move_l3_from_a3' type='continuous'>
        <parent link='a3'/>
        <child link='l3'/>
        <axis xyz='0.0 -0.9999999999932537 -3.673205103346574e-06'/>
        <origin rpy='0 0 0' xyz='0 0 0.11235'/>
        <limit lower='-3.14' upper='3.14'/>
    </joint>
    
    <link name='a4'>
        <visual>
            <origin rpy='-3.1415853071795863 0.0 0.0' xyz='0.0 0.0 0.11235'/>
            <geometry>
                <cylinder length='0.1' radius='0.05'/>
            </geometry>
            <material name='blue'/>
        </visual>
        <inertial>
            <mass value='0.8'/>
            <inertia ixx='1e-3' ixy='0' ixz='0' iyy='1e-3' iyz='0' izz='1e-3'/>
            <origin xyz='0 0 0.01'/>
        </inertial>
    </link>
    
    <joint name='fix_a4_to_l3' type='fixed'>
        <parent link='l3'/>
        <child link='a4'/>
        <origin rpy='0 0 0' xyz='0 0 0'/>
    </joint>
    
    <link name='l4'>
        <visual>
            <origin rpy='-0.0 0.0 0.0' xyz='0.0 0.0 0.042675'/>
            <geometry>
                <cylinder length='0.08535' radius='0.05'/>
            </geometry>
            <material name='red'/>
        </visual>
    </link>
    
    <joint name='move_l4_from_a4' type='continuous'>
        <parent link='a4'/>
        <child link='l4'/>
        <axis xyz='0.0 7.346410206643587e-06 -0.999999999973015'/>
        <origin rpy='0 0 0' xyz='0 0 0.08535'/>
        <limit lower='-3.14' upper='3.14'/>
    </joint>
    
    <link name='a5'>
        <visual>
            <origin rpy='1.5708 0.0 0.0' xyz='0.0 0.0 0.08535'/>
            <geometry>
                <cylinder length='0.1' radius='0.05'/>
            </geometry>
            <material name='blue'/>
        </visual>
        <inertial>
            <mass value='0.8'/>
            <inertia ixx='1e-3' ixy='0' ixz='0' iyy='1e-3' iyz='0' izz='1e-3'/>
            <origin xyz='0 0 0.01'/>
        </inertial>
    </link>
    
    <joint name='fix_a5_to_l4' type='fixed'>
        <parent link='l4'/>
        <child link='a5'/>
        <origin rpy='0 0 0' xyz='0 0 0'/>
    </joint>
    
    <link name='l5'>
        <visual>
            <origin rpy='-0.0 0.0 0.0' xyz='0.0 0.0 0.04095'/>
            <geometry>
                <cylinder length='0.0819' radius='0.05'/>
            </geometry>
            <material name='red'/>
        </visual>
    </link>
    
    <joint name='move_l5_from_a5' type='continuous'>
        <parent link='a5'/>
        <child link='l5'/>
        <axis xyz='0.0 -0.9999999999932536 -3.673205103346574e-06'/>
        <origin rpy='0 0 0' xyz='0 0 0.0819'/>
        <limit lower='-3.14' upper='3.14'/>
    </joint>
    </robot>
