<mujoco model="myCobot_pro600">
  <compiler meshdir="meshes" angle="radian" coordinate="local"/>

  <asset>
    <mesh name="base" file="base.stl" scale="0.001 0.001 0.001"/>
    <mesh name="link1" file="link1.stl" scale="0.001 0.001 0.001"/>
    <mesh name="link2" file="link2.stl" scale="0.001 0.001 0.001"/>
    <mesh name="link3" file="link3.stl" scale="0.001 0.001 0.001"/>
    <mesh name="link4" file="link4.stl" scale="0.001 0.001 0.001"/>
    <mesh name="link5" file="link5.stl" scale="0.001 0.001 0.001"/>
    <mesh name="link6" file="link6.stl" scale="0.001 0.001 0.001"/>
  </asset>

  <worldbody>
    <body name="base" pos="0 0 0">
      <geom type="mesh" mesh="base" rgba="1 1 1 1" contype="1" conaffinity="1" friction="0.8 0.1 0.1"/>

      <body name="link1" pos="0 0 0.19934">
        <joint name="joint2_to_joint1" type="hinge" axis="0 0 1" range="-3.14 3.14159" damping="0.1"/>
        <geom type="mesh" mesh="link1" euler="0 0 3.1415926" rgba="1 1 1 1" contype="1" conaffinity="1" friction="0.8 0.1 0.1"/>

        <body name="link2" pos="0 0 0" euler="1.5708 0 0">
          <joint name="joint3_to_joint2" type="hinge" axis="0 0 -1" range="-3.14159 3.14159" damping="0.1"/>
          <geom type="mesh" mesh="link2" pos="0 0 -0.080" euler="3.1415926 0 3.1415926" rgba="1 1 1 1" contype="1" conaffinity="1" friction="0.8 0.1 0.1"/>

          <body name="link3" pos="0.25 0 0">
            <joint name="joint4_to_joint3" type="hinge" axis="0 0 -1" range="-2.61 2.618" damping="0.1"/>
            <geom type="mesh" mesh="link3" pos="0 0 -0.0855" euler="3.1415926 0 3.1415926" rgba="1 1 1 1" contype="1" conaffinity="1" friction="0.8 0.1 0.1"/>

            <body name="link4" pos="0.25 0 -0.1091" euler="0 0 0">
              <joint name="joint5_to_joint4" type="hinge" axis="0 0 -1" range="-2.967 2.967" damping="0.1"/>
              <geom type="mesh" mesh="link4" euler="0 3.1415926 0" rgba="1 1 1 1" contype="1" conaffinity="1" friction="0.8 0.1 0.1"/>

              <body name="link5" pos="0 -0.108 0" euler="0 0 1.5708">
                <joint name="joint6_to_joint5" type="hinge" axis="0 0 1" range="-2.93 2.9321" damping="0.1"/>
                <geom type="mesh" mesh="link5" euler="0 -1.5708 1.5708" rgba="1 1 1 1" contype="1" conaffinity="1" friction="0.8 0.1 0.1"/>

                <body name="link6" pos="0 0 -0.05">
                  <joint name="joint6output_to_joint6" type="hinge" axis="-1 0 0" range="-3.03 3.0368" damping="0.1"/>
                  <geom type="mesh" mesh="link6" euler="0 3.14 0" rgba="1 1 1 1" contype="1" conaffinity="1" friction="0.8 0.1 0.1"/>
                </body>

              </body>
            </body>
          </body>
        </body>
      </body>
    </body>
  </worldbody>
</mujoco>
